Exception on /_dash-update-component [POST]
Traceback (most recent call last):
  File "C:\Users\Jesslyn\AppData\Roaming\Python\Python37\site-packages\flask\app.py", line 2446, in wsgi_app
    response = self.full_dispatch_request()
  File "C:\Users\Jesslyn\AppData\Roaming\Python\Python37\site-packages\flask\app.py", line 1951, in full_dispatch_request
    rv = self.handle_user_exception(e)
  File "C:\Users\Jesslyn\AppData\Roaming\Python\Python37\site-packages\flask\app.py", line 1820, in handle_user_exception
    reraise(exc_type, exc_value, tb)
  File "C:\Users\Jesslyn\AppData\Roaming\Python\Python37\site-packages\flask\_compat.py", line 39, in reraise
    raise value
  File "C:\Users\Jesslyn\AppData\Roaming\Python\Python37\site-packages\flask\app.py", line 1949, in full_dispatch_request
    rv = self.dispatch_request()
  File "C:\Users\Jesslyn\AppData\Roaming\Python\Python37\site-packages\flask\app.py", line 1935, in dispatch_request
    return self.view_functions[rule.endpoint](**req.view_args)
  File "C:\Users\Jesslyn\AppData\Roaming\Python\Python37\site-packages\dash\dash.py", line 1459, in dispatch
    response.set_data(self.callback_map[output]["callback"](*args))
  File "C:\Users\Jesslyn\AppData\Roaming\Python\Python37\site-packages\dash\dash.py", line 1339, in add_context
    output_value = func(*args, **kwargs)  # %% callback invoked %%
  File "c:/Users/Jesslyn/Documents/GitHub/fyp/Frontend/Code/Dashboard/controls-dash-sample.py", line 595, in update_all
    ),
KeyError: 'unknown'
Exception on /_dash-update-component [POST]
Traceback (most recent call last):
  File "C:\Users\Jesslyn\AppData\Roaming\Python\Python37\site-packages\flask\app.py", line 2446, in wsgi_app
    response = self.full_dispatch_request()
  File "C:\Users\Jesslyn\AppData\Roaming\Python\Python37\site-packages\flask\app.py", line 1951, in full_dispatch_request
    rv = self.handle_user_exception(e)
  File "C:\Users\Jesslyn\AppData\Roaming\Python\Python37\site-packages\flask\app.py", line 1820, in handle_user_exception
    reraise(exc_type, exc_value, tb)
  File "C:\Users\Jesslyn\AppData\Roaming\Python\Python37\site-packages\flask\_compat.py", line 39, in reraise
    raise value
  File "C:\Users\Jesslyn\AppData\Roaming\Python\Python37\site-packages\flask\app.py", line 1949, in full_dispatch_request
    rv = self.dispatch_request()
  File "C:\Users\Jesslyn\AppData\Roaming\Python\Python37\site-packages\flask\app.py", line 1935, in dispatch_request
    return self.view_functions[rule.endpoint](**req.view_args)
  File "C:\Users\Jesslyn\AppData\Roaming\Python\Python37\site-packages\dash\dash.py", line 1459, in dispatch
    response.set_data(self.callback_map[output]["callback"](*args))
  File "C:\Users\Jesslyn\AppData\Roaming\Python\Python37\site-packages\dash\dash.py", line 1339, in add_context
    output_value = func(*args, **kwargs)  # %% callback invoked %%
  File "c:/Users/Jesslyn/Documents/GitHub/fyp/Frontend/Code/Dashboard/controls-dash-sample.py", line 519, in update_all
    tdict, fdict = generate_tnm_chart_data(df, cause)
  File "c:/Users/Jesslyn/Documents/GitHub/fyp/Frontend/Code/Dashboard/controls-dash-sample.py", line 113, in generate_tnm_chart_data
    TNM_dict = dict(sorted(TNM_dict.items(), key=lambda x:operator.getitem(x[1],'breast cancer related')))
  File "c:/Users/Jesslyn/Documents/GitHub/fyp/Frontend/Code/Dashboard/controls-dash-sample.py", line 113, in <lambda>
    TNM_dict = dict(sorted(TNM_dict.items(), key=lambda x:operator.getitem(x[1],'breast cancer related')))
KeyError: 'breast cancer related'
